Workbook

Sheet Dashboard
B1: Painel de coleta de preços — FNDE Centro-Oeste (GO)
B2: Consolidado dos arquivos resumo_coleta.csv · EPI / Uniforme, Limpeza e Higiene, Limpeza Predial · meta de 5 preços por item
B4: Itens | F4: Preços coletados | J4: Meta de preços | N4: Cobertura | R4: Itens completos | V4: Itens sem preço
B5: =Resumo!B7 | F5: =Resumo!C7 | J5: =Resumo!E7 | N5: =Resumo!F7 | R5: =Resumo!G7 | V5: =Resumo!I7
B42: Detalhamento por item nas abas “Itens …”; base consolidada na aba Dados (tabela editável — os gráficos se atualizam).

Sheet Resumo
A1: Resumo por grupo
A3: Grupo | B3: Itens | C3: Preços coletados | D3: Faltam | E3: Meta | F3: % cobertura | G3: Itens completos | H3: Itens parciais | I3: Itens sem preço | J3: Links aproveitáveis | K3: Sem preço visível
A4: EPI / UNIFORME | B4: =COUNTIF(Dados!$B$2:$B$121,$A4) | C4: =SUMIF(Dados!$B$2:$B$121,$A4,Dados!$D$2:$D$121) | D4: =SUMIF(Dados!$B$2:$B$121,$A4,Dados!$E$2:$E$121) | E4: =SUMIF(Dados!$B$2:$B$121,$A4,Dados!$F$2:$F$121) | F4: =IF(E4=0,0,C4/E4) | G4: =COUNTIFS(Dados!$B$2:$B$121,$A4,Dados!$J$2:$J$121,"Completo") | H4: =COUNTIFS(Dados!$B$2:$B$121,$A4,Dados!$J$2:$J$121,"Parcial") | I4: =COUNTIFS(Dados!$B$2:$B$121,$A4,Dados!$J$2:$J$121,"Sem preço") | J4: =IF(COUNTIFS(Dados!$B$2:$B$121,$A4,Dados!$H$2:$H$121,"<>")=0,"n/d",SUMIF(Dados!$B$2:$B$121,$A4,Dados!$H$2:$H$121)) | K4: =IF(COUNTIFS(Dados!$B$2:$B$121,$A4,Dados!$I$2:$I$121,"<>")=0,"n/d",SUMIF(Dados!$B$2:$B$121,$A4,Dados!$I$2:$I$121))
A5: LIMPEZA E HIGIENE | B5: =COUNTIF(Dados!$B$2:$B$121,$A5) | C5: =SUMIF(Dados!$B$2:$B$121,$A5,Dados!$D$2:$D$121) | D5: =SUMIF(Dados!$B$2:$B$121,$A5,Dados!$E$2:$E$121) | E5: =SUMIF(Dados!$B$2:$B$121,$A5,Dados!$F$2:$F$121) | F5: =IF(E5=0,0,C5/E5) | G5: =COUNTIFS(Dados!$B$2:$B$121,$A5,Dados!$J$2:$J$121,"Completo") | H5: =COUNTIFS(Dados!$B$2:$B$121,$A5,Dados!$J$2:$J$121,"Parcial") | I5: =COUNTIFS(Dados!$B$2:$B$121,$A5,Dados!$J$2:$J$121,"Sem preço") | J5: =IF(COUNTIFS(Dados!$B$2:$B$121,$A5,Dados!$H$2:$H$121,"<>")=0,"n/d",SUMIF(Dados!$B$2:$B$121,$A5,Dados!$H$2:$H$121)) | K5: =IF(COUNTIFS(Dados!$B$2:$B$121,$A5,Dados!$I$2:$I$121,"<>")=0,"n/d",SUMIF(Dados!$B$2:$B$121,$A5,Dados!$I$2:$I$121))
A6: LIMPEZA PREDIAL | B6: =COUNTIF(Dados!$B$2:$B$121,$A6) | C6: =SUMIF(Dados!$B$2:$B$121,$A6,Dados!$D$2:$D$121) | D6: =SUMIF(Dados!$B$2:$B$121,$A6,Dados!$E$2:$E$121) | E6: =SUMIF(Dados!$B$2:$B$121,$A6,Dados!$F$2:$F$121) | F6: =IF(E6=0,0,C6/E6) | G6: =COUNTIFS(Dados!$B$2:$B$121,$A6,Dados!$J$2:$J$121,"Completo") | H6: =COUNTIFS(Dados!$B$2:$B$121,$A6,Dados!$J$2:$J$121,"Parcial") | I6: =COUNTIFS(Dados!$B$2:$B$121,$A6,Dados!$J$2:$J$121,"Sem preço") | J6: =IF(COUNTIFS(Dados!$B$2:$B$121,$A6,Dados!$H$2:$H$121,"<>")=0,"n/d",SUMIF(Dados!$B$2:$B$121,$A6,Dados!$H$2:$H$121)) | K6: =IF(COUNTIFS(Dados!$B$2:$B$121,$A6,Dados!$I$2:$I$121,"<>")=0,"n/d",SUMIF(Dados!$B$2:$B$121,$A6,Dados!$I$2:$I$121))
A7: TOTAL | B7: =SUM(B4:B6) | C7: =SUM(C4:C6) | D7: =SUM(D4:D6) | E7: =SUM(E4:E6) | F7: =IF(E7=0,0,C7/E7) | G7: =SUM(G4:G6) | H7: =SUM(H4:H6) | I7: =SUM(I4:I6) | J7: =SUM(J4:J6) | K7: =SUM(K4:K6)
A10: Distribuição dos itens por nº de preços coletados
A12: Preços coletados | B12: EPI / UNIFORME | C12: LIMPEZA E HIGIENE | D12: LIMPEZA PREDIAL | E12: Total | G12: Status | H12: Itens
A13: 0 de 5 | B13: =COUNTIFS(Dados!$B$2:$B$121,B$12,Dados!$D$2:$D$121,0) | C13: =COUNTIFS(Dados!$B$2:$B$121,C$12,Dados!$D$2:$D$121,0) | D13: =COUNTIFS(Dados!$B$2:$B$121,D$12,Dados!$D$2:$D$121,0) | E13: =SUM(B13:D13) | G13: Completo (5/5) | H13: =G7
A14: 1 de 5 | B14: =COUNTIFS(Dados!$B$2:$B$121,B$12,Dados!$D$2:$D$121,1) | C14: =COUNTIFS(Dados!$B$2:$B$121,C$12,Dados!$D$2:$D$121,1) | D14: =COUNTIFS(Dados!$B$2:$B$121,D$12,Dados!$D$2:$D$121,1) | E14: =SUM(B14:D14) | G14: Parcial | H14: =H7
A15: 2 de 5 | B15: =COUNTIFS(Dados!$B$2:$B$121,B$12,Dados!$D$2:$D$121,2) | C15: =COUNTIFS(Dados!$B$2:$B$121,C$12,Dados!$D$2:$D$121,2) | D15: =COUNTIFS(Dados!$B$2:$B$121,D$12,Dados!$D$2:$D$121,2) | E15: =SUM(B15:D15) | G15: Sem preço | H15: =I7
A16: 3 de 5 | B16: =COUNTIFS(Dados!$B$2:$B$121,B$12,Dados!$D$2:$D$121,3) | C16: =COUNTIFS(Dados!$B$2:$B$121,C$12,Dados!$D$2:$D$121,3) | D16: =COUNTIFS(Dados!$B$2:$B$121,D$12,Dados!$D$2:$D$121,3) | E16: =SUM(B16:D16)
A17: 4 de 5 | B17: =COUNTIFS(Dados!$B$2:$B$121,B$12,Dados!$D$2:$D$121,4) | C17: =COUNTIFS(Dados!$B$2:$B$121,C$12,Dados!$D$2:$D$121,4) | D17: =COUNTIFS(Dados!$B$2:$B$121,D$12,Dados!$D$2:$D$121,4) | E17: =SUM(B17:D17)
A18: 5 de 5 | B18: =COUNTIFS(Dados!$B$2:$B$121,B$12,Dados!$D$2:$D$121,5) | C18: =COUNTIFS(Dados!$B$2:$B$121,C$12,Dados!$D$2:$D$121,5) | D18: =COUNTIFS(Dados!$B$2:$B$121,D$12,Dados!$D$2:$D$121,5) | E18: =SUM(B18:D18)

Sheet Dados
A1: ID FGV | B1: Grupo | C1: UF | D1: Preços coletados | E1: Faltam | F1: Meta (preços) | G1: % coletado | H1: Link aproveitável | I1: Sem preço visível (col. P) | J1: Status
A2: 1104 | B2: EPI / UNIFORME | C2: GO | D2: 3 | E2: 2 | F2: =D2+E2 | G2: =IF(F2=0,0,D2/F2) | H2: 2 | J2: =IF(E2=0,"Completo",IF(D2=0,"Sem preço","Parcial"))
A3: 1105 | B3: EPI / UNIFORME | C3: GO | D3: 2 | E3: 3 | F3: =D3+E3 | G3: =IF(F3=0,0,D3/F3) | H3: 2 | J3: =IF(E3=0,"Completo",IF(D3=0,"Sem preço","Parcial"))
A4: 1106 | B4: EPI / UNIFORME | C4: GO | D4: 0 | E4: 5 | F4: =D4+E4 | G4: =IF(F4=0,0,D4/F4) | H4: 0 | J4: =IF(E4=0,"Completo",IF(D4=0,"Sem preço","Parcial"))
A5: 1107 | B5: EPI / UNIFORME | C5: GO | D5: 0 | E5: 5 | F5: =D5+E5 | G5: =IF(F5=0,0,D5/F5) | H5: 1 | J5: =IF(E5=0,"Completo",IF(D5=0,"Sem preço","Parcial"))
A6: 1108 | B6: EPI / UNIFORME | C6: GO | D6: 4 | E6: 1 | F6: =D6+E6 | G6: =IF(F6=0,0,D6/F6) | H6: 0 | J6: =IF(E6=0,"Completo",IF(D6=0,"Sem preço","Parcial"))
A7: 1109 | B7: EPI / UNIFORME | C7: GO | D7: 3 | E7: 2 | F7: =D7+E7 | G7: =IF(F7=0,0,D7/F7) | H7: 0 | J7: =IF(E7=0,"Completo",IF(D7=0,"Sem preço","Parcial"))
A8: 1110 | B8: EPI / UNIFORME | C8: GO | D8: 5 | E8: 0 | F8: =D8+E8 | G8: =IF(F8=0,0,D8/F8) | H8: 0 | J8: =IF(E8=0,"Completo",IF(D8=0,"Sem preço","Parcial"))
A9: 1111 | B9: EPI / UNIFORME | C9: GO | D9: 3 | E9: 2 | F9: =D9+E9 | G9: =IF(F9=0,0,D9/F9) | H9: 0 | J9: =IF(E9=0,"Completo",IF(D9=0,"Sem preço","Parcial"))
A10: 1112 | B10: EPI / UNIFORME | C10: GO | D10: 1 | E10: 4 | F10: =D10+E10 | G10: =IF(F10=0,0,D10/F10) | H10: 0 | J10: =IF(E10=0,"Completo",IF(D10=0,"Sem preço","Parcial"))
A11: 1113 | B11: EPI / UNIFORME | C11: GO | D11: 5 | E11: 0 | F11: =D11+E11 | G11: =IF(F11=0,0,D11/F11) | H11: 1 | J11: =IF(E11=0,"Completo",IF(D11=0,"Sem preço","Parcial"))
A12: 1114 | B12: EPI / UNIFORME | C12: GO | D12: 3 | E12: 2 | F12: =D12+E12 | G12: =IF(F12=0,0,D12/F12) | H12: 0 | J12: =IF(E12=0,"Completo",IF(D12=0,"Sem preço","Parcial"))
A13: 1115 | B13: EPI / UNIFORME | C13: GO | D13: 4 | E13: 1 | F13: =D13+E13 | G13: =IF(F13=0,0,D13/F13) | H13: 0 | J13: =IF(E13=0,"Completo",IF(D13=0,"Sem preço","Parcial"))
... A17: 1119 | B17: EPI / UNIFORME | C17: GO | D17: 4 | E17: 1 | F17: =D17+E17 | G17: =IF(F17=0,0,D17/F17) | H17: 0 | J17: =IF(E17=0,"Completo",IF(D17=0,"Sem preço","Parcial"))
A18: 1000 | B18: LIMPEZA E HIGIENE | C18: GO | D18: 4 | E18: 1 | F18: =D18+E18 | G18: =IF(F18=0,0,D18/F18) | I18: 0 | J18: =IF(E18=0,"Completo",IF(D18=0,"Sem preço","Parcial"))
A19: 1001 | B19: LIMPEZA E HIGIENE | C19: GO | D19: 3 | E19: 2 | F19: =D19+E19 | G19: =IF(F19=0,0,D19/F19) | I19: 1 | J19: =IF(E19=0,"Completo",IF(D19=0,"Sem preço","Parcial"))
A20: 1002 | B20: LIMPEZA E HIGIENE | C20: GO | D20: 3 | E20: 2 | F20: =D20+E20 | G20: =IF(F20=0,0,D20/F20) | I20: 1 | J20: =IF(E20=0,"Completo",IF(D20=0,"Sem preço","Parcial"))
A21: 1003 | B21: LIMPEZA E HIGIENE | C21: GO | D21: 4 | E21: 1 | F21: =D21+E21 | G21: =IF(F21=0,0,D21/F21) | I21: 1 | J21: =IF(E21=0,"Completo",IF(D21=0,"Sem preço","Parcial"))
A22: 1004 | B22: LIMPEZA E HIGIENE | C22: GO | D22: 5 | E22: 0 | F22: =D22+E22 | G22: =IF(F22=0,0,D22/F22) | I22: 0 | J22: =IF(E22=0,"Completo",IF(D22=0,"Sem preço","Parcial"))
A23: 1005 | B23: LIMPEZA E HIGIENE | C23: GO | D23: 0 | E23: 5 | F23: =D23+E23 | G23: =IF(F23=0,0,D23/F23) | I23: 0 | J23: =IF(E23=0,"Completo",IF(D23=0,"Sem preço","Parcial"))
A24: 1006 | B24: LIMPEZA E HIGIENE | C24: GO | D24: 0 | E24: 5 | F24: =D24+E24 | G24: =IF(F24=0,0,D24/F24) | I24: 0 | J24: =IF(E24=0,"Completo",IF(D24=0,"Sem preço","Parcial"))
A25: 1007 | B25: LIMPEZA E HIGIENE | C25: GO | D25: 1 | E25: 4 | F25: =D25+E25 | G25: =IF(F25=0,0,D25/F25) | I25: 0 | J25: =IF(E25=0,"Completo",IF(D25=0,"Sem preço","Parcial"))
A26: 1008 | B26: LIMPEZA E HIGIENE | C26: GO | D26: 3 | E26: 2 | F26: =D26+E26 | G26: =IF(F26=0,0,D26/F26) | I26: 1 | J26: =IF(E26=0,"Completo",IF(D26=0,"Sem preço","Parcial"))
A27: 1009 | B27: LIMPEZA E HIGIENE | C27: GO | D27: 4 | E27: 1 | F27: =D27+E27 | G27: =IF(F27=0,0,D27/F27) | I27: 0 | J27: =IF(E27=0,"Completo",IF(D27=0,"Sem preço","Parcial"))
A28: 1010 | B28: LIMPEZA E HIGIENE | C28: GO | D28: 2 | E28: 3 | F28: =D28+E28 | G28: =IF(F28=0,0,D28/F28) | I28: 0 | J28: =IF(E28=0,"Completo",IF(D28=0,"Sem preço","Parcial"))
A29: 1011 | B29: LIMPEZA E HIGIENE | C29: GO | D29: 3 | E29: 2 | F29: =D29+E29 | G29: =IF(F29=0,0,D29/F29) | I29: 0 | J29: =IF(E29=0,"Completo",IF(D29=0,"Sem preço","Parcial"))
... A73: 1055 | B73: LIMPEZA E HIGIENE | C73: GO | D73: 3 | E73: 2 | F73: =D73+E73 | G73: =IF(F73=0,0,D73/F73) | I73: 0 | J73: =IF(E73=0,"Completo",IF(D73=0,"Sem preço","Parcial"))
A74: 1056 | B74: LIMPEZA PREDIAL | C74: GO | D74: 1 | E74: 4 | F74: =D74+E74 | G74: =IF(F74=0,0,D74/F74) | H74: 0 | I74: 0 | J74: =IF(E74=0,"Completo",IF(D74=0,"Sem preço","Parcial"))
A75: 1057 | B75: LIMPEZA PREDIAL | C75: GO | D75: 2 | E75: 3 | F75: =D75+E75 | G75: =IF(F75=0,0,D75/F75) | H75: 0 | I75: 0 | J75: =IF(E75=0,"Completo",IF(D75=0,"Sem preço","Parcial"))
A76: 1058 | B76: LIMPEZA PREDIAL | C76: GO | D76: 1 | E76: 4 | F76: =D76+E76 | G76: =IF(F76=0,0,D76/F76) | H76: 1 | I76: 1 | J76: =IF(E76=0,"Completo",IF(D76=0,"Sem preço","Parcial"))
A77: 1059 | B77: LIMPEZA PREDIAL | C77: GO | D77: 1 | E77: 4 | F77: =D77+E77 | G77: =IF(F77=0,0,D77/F77) | H77: 0 | I77: 0 | J77: =IF(E77=0,"Completo",IF(D77=0,"Sem preço","Parcial"))
A78: 1060 | B78: LIMPEZA PREDIAL | C78: GO | D78: 1 | E78: 4 | F78: =D78+E78 | G78: =IF(F78=0,0,D78/F78) | H78: 0 | I78: 0 | J78: =IF(E78=0,"Completo",IF(D78=0,"Sem preço","Parcial"))
A79: 1061 | B79: LIMPEZA PREDIAL | C79: GO | D79: 4 | E79: 1 | F79: =D79+E79 | G79: =IF(F79=0,0,D79/F79) | H79: 1 | I79: 1 | J79: =IF(E79=0,"Completo",IF(D79=0,"Sem preço","Parcial"))
A80: 1062 | B80: LIMPEZA PREDIAL | C80: GO | D80: 0 | E80: 5 | F80: =D80+E80 | G80: =IF(F80=0,0,D80/F80) | H80: 0 | I80: 0 | J80: =IF(E80=0,"Completo",IF(D80=0,"Sem preço","Parcial"))
A81: 1063 | B81: LIMPEZA PREDIAL | C81: GO | D81: 4 | E81: 1 | F81: =D81+E81 | G81: =IF(F81=0,0,D81/F81) | H81: 1 | I81: 0 | J81: =IF(E81=0,"Completo",IF(D81=0,"Sem preço","Parcial"))
A82: 1064 | B82: LIMPEZA PREDIAL | C82: GO | D82: 0 | E82: 5 | F82: =D82+E82 | G82: =IF(F82=0,0,D82/F82) | H82: 0 | I82: 0 | J82: =IF(E82=0,"Completo",IF(D82=0,"Sem preço","Parcial"))
A83: 1065 | B83: LIMPEZA PREDIAL | C83: GO | D83: 0 | E83: 5 | F83: =D83+E83 | G83: =IF(F83=0,0,D83/F83) | H83: 0 | I83: 0 | J83: =IF(E83=0,"Completo",IF(D83=0,"Sem preço","Parcial"))
A84: 1066 | B84: LIMPEZA PREDIAL | C84: GO | D84: 0 | E84: 5 | F84: =D84+E84 | G84: =IF(F84=0,0,D84/F84) | H84: 0 | I84: 0 | J84: =IF(E84=0,"Completo",IF(D84=0,"Sem preço","Parcial"))
A85: 1067 | B85: LIMPEZA PREDIAL | C85: GO | D85: 0 | E85: 5 | F85: =D85+E85 | G85: =IF(F85=0,0,D85/F85) | H85: 2 | I85: 1 | J85: =IF(E85=0,"Completo",IF(D85=0,"Sem preço","Parcial"))
... A121: 1103 | B121: LIMPEZA PREDIAL | C121: GO | D121: 2 | E121: 3 | F121: =D121+E121 | G121: =IF(F121=0,0,D121/F121) | H121: 1 | I121: 0 | J121: =IF(E121=0,"Completo",IF(D121=0,"Sem preço","Parcial"))
...

Sheet Itens EPI-UNIFORME
A1: ID FGV | B1: Coletados | C1: Faltam
A2: 1104 | B2: =INDEX(Dados!$D$2:$D$121,MATCH(1104,Dados!$A$2:$A$121,0)) | C2: =INDEX(Dados!$E$2:$E$121,MATCH(1104,Dados!$A$2:$A$121,0))
A3: 1105 | B3: =INDEX(Dados!$D$2:$D$121,MATCH(1105,Dados!$A$2:$A$121,0)) | C3: =INDEX(Dados!$E$2:$E$121,MATCH(1105,Dados!$A$2:$A$121,0))
A4: 1106 | B4: =INDEX(Dados!$D$2:$D$121,MATCH(1106,Dados!$A$2:$A$121,0)) | C4: =INDEX(Dados!$E$2:$E$121,MATCH(1106,Dados!$A$2:$A$121,0))
A5: 1107 | B5: =INDEX(Dados!$D$2:$D$121,MATCH(1107,Dados!$A$2:$A$121,0)) | C5: =INDEX(Dados!$E$2:$E$121,MATCH(1107,Dados!$A$2:$A$121,0))
A6: 1108 | B6: =INDEX(Dados!$D$2:$D$121,MATCH(1108,Dados!$A$2:$A$121,0)) | C6: =INDEX(Dados!$E$2:$E$121,MATCH(1108,Dados!$A$2:$A$121,0))
A7: 1109 | B7: =INDEX(Dados!$D$2:$D$121,MATCH(1109,Dados!$A$2:$A$121,0)) | C7: =INDEX(Dados!$E$2:$E$121,MATCH(1109,Dados!$A$2:$A$121,0))
A8: 1110 | B8: =INDEX(Dados!$D$2:$D$121,MATCH(1110,Dados!$A$2:$A$121,0)) | C8: =INDEX(Dados!$E$2:$E$121,MATCH(1110,Dados!$A$2:$A$121,0))
A9: 1111 | B9: =INDEX(Dados!$D$2:$D$121,MATCH(1111,Dados!$A$2:$A$121,0)) | C9: =INDEX(Dados!$E$2:$E$121,MATCH(1111,Dados!$A$2:$A$121,0))
A10: 1112 | B10: =INDEX(Dados!$D$2:$D$121,MATCH(1112,Dados!$A$2:$A$121,0)) | C10: =INDEX(Dados!$E$2:$E$121,MATCH(1112,Dados!$A$2:$A$121,0))
A11: 1113 | B11: =INDEX(Dados!$D$2:$D$121,MATCH(1113,Dados!$A$2:$A$121,0)) | C11: =INDEX(Dados!$E$2:$E$121,MATCH(1113,Dados!$A$2:$A$121,0))
A12: 1114 | B12: =INDEX(Dados!$D$2:$D$121,MATCH(1114,Dados!$A$2:$A$121,0)) | C12: =INDEX(Dados!$E$2:$E$121,MATCH(1114,Dados!$A$2:$A$121,0))
A13: 1115 | B13: =INDEX(Dados!$D$2:$D$121,MATCH(1115,Dados!$A$2:$A$121,0)) | C13: =INDEX(Dados!$E$2:$E$121,MATCH(1115,Dados!$A$2:$A$121,0))
A14: 1116 | B14: =INDEX(Dados!$D$2:$D$121,MATCH(1116,Dados!$A$2:$A$121,0)) | C14: =INDEX(Dados!$E$2:$E$121,MATCH(1116,Dados!$A$2:$A$121,0))
A15: 1117 | B15: =INDEX(Dados!$D$2:$D$121,MATCH(1117,Dados!$A$2:$A$121,0)) | C15: =INDEX(Dados!$E$2:$E$121,MATCH(1117,Dados!$A$2:$A$121,0))
A16: 1118 | B16: =INDEX(Dados!$D$2:$D$121,MATCH(1118,Dados!$A$2:$A$121,0)) | C16: =INDEX(Dados!$E$2:$E$121,MATCH(1118,Dados!$A$2:$A$121,0))
A17: 1119 | B17: =INDEX(Dados!$D$2:$D$121,MATCH(1119,Dados!$A$2:$A$121,0)) | C17: =INDEX(Dados!$E$2:$E$121,MATCH(1119,Dados!$A$2:$A$121,0))

Sheet Itens LIMPEZA E HIGIENE
A1: ID FGV | B1: Coletados | C1: Faltam
A2: 1000 | B2: =INDEX(Dados!$D$2:$D$121,MATCH(1000,Dados!$A$2:$A$121,0)) | C2: =INDEX(Dados!$E$2:$E$121,MATCH(1000,Dados!$A$2:$A$121,0))
A3: 1001 | B3: =INDEX(Dados!$D$2:$D$121,MATCH(1001,Dados!$A$2:$A$121,0)) | C3: =INDEX(Dados!$E$2:$E$121,MATCH(1001,Dados!$A$2:$A$121,0))
A4: 1002 | B4: =INDEX(Dados!$D$2:$D$121,MATCH(1002,Dados!$A$2:$A$121,0)) | C4: =INDEX(Dados!$E$2:$E$121,MATCH(1002,Dados!$A$2:$A$121,0))
A5: 1003 | B5: =INDEX(Dados!$D$2:$D$121,MATCH(1003,Dados!$A$2:$A$121,0)) | C5: =INDEX(Dados!$E$2:$E$121,MATCH(1003,Dados!$A$2:$A$121,0))
A6: 1004 | B6: =INDEX(Dados!$D$2:$D$121,MATCH(1004,Dados!$A$2:$A$121,0)) | C6: =INDEX(Dados!$E$2:$E$121,MATCH(1004,Dados!$A$2:$A$121,0))
A7: 1005 | B7: =INDEX(Dados!$D$2:$D$121,MATCH(1005,Dados!$A$2:$A$121,0)) | C7: =INDEX(Dados!$E$2:$E$121,MATCH(1005,Dados!$A$2:$A$121,0))
A8: 1006 | B8: =INDEX(Dados!$D$2:$D$121,MATCH(1006,Dados!$A$2:$A$121,0)) | C8: =INDEX(Dados!$E$2:$E$121,MATCH(1006,Dados!$A$2:$A$121,0))
A9: 1007 | B9: =INDEX(Dados!$D$2:$D$121,MATCH(1007,Dados!$A$2:$A$121,0)) | C9: =INDEX(Dados!$E$2:$E$121,MATCH(1007,Dados!$A$2:$A$121,0))
A10: 1008 | B10: =INDEX(Dados!$D$2:$D$121,MATCH(1008,Dados!$A$2:$A$121,0)) | C10: =INDEX(Dados!$E$2:$E$121,MATCH(1008,Dados!$A$2:$A$121,0))
A11: 1009 | B11: =INDEX(Dados!$D$2:$D$121,MATCH(1009,Dados!$A$2:$A$121,0)) | C11: =INDEX(Dados!$E$2:$E$121,MATCH(1009,Dados!$A$2:$A$121,0))
A12: 1010 | B12: =INDEX(Dados!$D$2:$D$121,MATCH(1010,Dados!$A$2:$A$121,0)) | C12: =INDEX(Dados!$E$2:$E$121,MATCH(1010,Dados!$A$2:$A$121,0))
A13: 1011 | B13: =INDEX(Dados!$D$2:$D$121,MATCH(1011,Dados!$A$2:$A$121,0)) | C13: =INDEX(Dados!$E$2:$E$121,MATCH(1011,Dados!$A$2:$A$121,0))
A14: 1012 | B14: =INDEX(Dados!$D$2:$D$121,MATCH(1012,Dados!$A$2:$A$121,0)) | C14: =INDEX(Dados!$E$2:$E$121,MATCH(1012,Dados!$A$2:$A$121,0))
A15: 1013 | B15: =INDEX(Dados!$D$2:$D$121,MATCH(1013,Dados!$A$2:$A$121,0)) | C15: =INDEX(Dados!$E$2:$E$121,MATCH(1013,Dados!$A$2:$A$121,0))
A16: 1014 | B16: =INDEX(Dados!$D$2:$D$121,MATCH(1014,Dados!$A$2:$A$121,0)) | C16: =INDEX(Dados!$E$2:$E$121,MATCH(1014,Dados!$A$2:$A$121,0))
A17: 1015 | B17: =INDEX(Dados!$D$2:$D$121,MATCH(1015,Dados!$A$2:$A$121,0)) | C17: =INDEX(Dados!$E$2:$E$121,MATCH(1015,Dados!$A$2:$A$121,0))
A18: 1016 | B18: =INDEX(Dados!$D$2:$D$121,MATCH(1016,Dados!$A$2:$A$121,0)) | C18: =INDEX(Dados!$E$2:$E$121,MATCH(1016,Dados!$A$2:$A$121,0))
A19: 1017 | B19: =INDEX(Dados!$D$2:$D$121,MATCH(1017,Dados!$A$2:$A$121,0)) | C19: =INDEX(Dados!$E$2:$E$121,MATCH(1017,Dados!$A$2:$A$121,0))
A20: 1018 | B20: =INDEX(Dados!$D$2:$D$121,MATCH(1018,Dados!$A$2:$A$121,0)) | C20: =INDEX(Dados!$E$2:$E$121,MATCH(1018,Dados!$A$2:$A$121,0))
A21: 1019 | B21: =INDEX(Dados!$D$2:$D$121,MATCH(1019,Dados!$A$2:$A$121,0)) | C21: =INDEX(Dados!$E$2:$E$121,MATCH(1019,Dados!$A$2:$A$121,0))
A22: 1020 | B22: =INDEX(Dados!$D$2:$D$121,MATCH(1020,Dados!$A$2:$A$121,0)) | C22: =INDEX(Dados!$E$2:$E$121,MATCH(1020,Dados!$A$2:$A$121,0))
A23: 1021 | B23: =INDEX(Dados!$D$2:$D$121,MATCH(1021,Dados!$A$2:$A$121,0)) | C23: =INDEX(Dados!$E$2:$E$121,MATCH(1021,Dados!$A$2:$A$121,0))
A24: 1022 | B24: =INDEX(Dados!$D$2:$D$121,MATCH(1022,Dados!$A$2:$A$121,0)) | C24: =INDEX(Dados!$E$2:$E$121,MATCH(1022,Dados!$A$2:$A$121,0))
A25: 1023 | B25: =INDEX(Dados!$D$2:$D$121,MATCH(1023,Dados!$A$2:$A$121,0)) | C25: =INDEX(Dados!$E$2:$E$121,MATCH(1023,Dados!$A$2:$A$121,0))
A26: 1024 | B26: =INDEX(Dados!$D$2:$D$121,MATCH(1024,Dados!$A$2:$A$121,0)) | C26: =INDEX(Dados!$E$2:$E$121,MATCH(1024,Dados!$A$2:$A$121,0))
A27: 1025 | B27: =INDEX(Dados!$D$2:$D$121,MATCH(1025,Dados!$A$2:$A$121,0)) | C27: =INDEX(Dados!$E$2:$E$121,MATCH(1025,Dados!$A$2:$A$121,0))
A28: 1026 | B28: =INDEX(Dados!$D$2:$D$121,MATCH(1026,Dados!$A$2:$A$121,0)) | C28: =INDEX(Dados!$E$2:$E$121,MATCH(1026,Dados!$A$2:$A$121,0))
A29: 1027 | B29: =INDEX(Dados!$D$2:$D$121,MATCH(1027,Dados!$A$2:$A$121,0)) | C29: =INDEX(Dados!$E$2:$E$121,MATCH(1027,Dados!$A$2:$A$121,0))
A30: 1028 | B30: =INDEX(Dados!$D$2:$D$121,MATCH(1028,Dados!$A$2:$A$121,0)) | C30: =INDEX(Dados!$E$2:$E$121,MATCH(1028,Dados!$A$2:$A$121,0))
A31: 1029 | B31: =INDEX(Dados!$D$2:$D$121,MATCH(1029,Dados!$A$2:$A$121,0)) | C31: =INDEX(Dados!$E$2:$E$121,MATCH(1029,Dados!$A$2:$A$121,0))
A32: 1030 | B32: =INDEX(Dados!$D$2:$D$121,MATCH(1030,Dados!$A$2:$A$121,0)) | C32: =INDEX(Dados!$E$2:$E$121,MATCH(1030,Dados!$A$2:$A$121,0))
A33: 1031 | B33: =INDEX(Dados!$D$2:$D$121,MATCH(1031,Dados!$A$2:$A$121,0)) | C33: =INDEX(Dados!$E$2:$E$121,MATCH(1031,Dados!$A$2:$A$121,0))
A34: 1032 | B34: =INDEX(Dados!$D$2:$D$121,MATCH(1032,Dados!$A$2:$A$121,0)) | C34: =INDEX(Dados!$E$2:$E$121,MATCH(1032,Dados!$A$2:$A$121,0))
A35: 1033 | B35: =INDEX(Dados!$D$2:$D$121,MATCH(1033,Dados!$A$2:$A$121,0)) | C35: =INDEX(Dados!$E$2:$E$121,MATCH(1033,Dados!$A$2:$A$121,0))
A36: 1034 | B36: =INDEX(Dados!$D$2:$D$121,MATCH(1034,Dados!$A$2:$A$121,0)) | C36: =INDEX(Dados!$E$2:$E$121,MATCH(1034,Dados!$A$2:$A$121,0))
A37: 1035 | B37: =INDEX(Dados!$D$2:$D$121,MATCH(1035,Dados!$A$2:$A$121,0)) | C37: =INDEX(Dados!$E$2:$E$121,MATCH(1035,Dados!$A$2:$A$121,0))
A38: 1036 | B38: =INDEX(Dados!$D$2:$D$121,MATCH(1036,Dados!$A$2:$A$121,0)) | C38: =INDEX(Dados!$E$2:$E$121,MATCH(1036,Dados!$A$2:$A$121,0))
A39: 1037 | B39: =INDEX(Dados!$D$2:$D$121,MATCH(1037,Dados!$A$2:$A$121,0)) | C39: =INDEX(Dados!$E$2:$E$121,MATCH(1037,Dados!$A$2:$A$121,0))
A40: 1038 | B40: =INDEX(Dados!$D$2:$D$121,MATCH(1038,Dados!$A$2:$A$121,0)) | C40: =INDEX(Dados!$E$2:$E$121,MATCH(1038,Dados!$A$2:$A$121,0))
...

Sheet Itens LIMPEZA PREDIAL
A1: ID FGV | B1: Coletados | C1: Faltam
A2: 1056 | B2: =INDEX(Dados!$D$2:$D$121,MATCH(1056,Dados!$A$2:$A$121,0)) | C2: =INDEX(Dados!$E$2:$E$121,MATCH(1056,Dados!$A$2:$A$121,0))
A3: 1057 | B3: =INDEX(Dados!$D$2:$D$121,MATCH(1057,Dados!$A$2:$A$121,0)) | C3: =INDEX(Dados!$E$2:$E$121,MATCH(1057,Dados!$A$2:$A$121,0))
A4: 1058 | B4: =INDEX(Dados!$D$2:$D$121,MATCH(1058,Dados!$A$2:$A$121,0)) | C4: =INDEX(Dados!$E$2:$E$121,MATCH(1058,Dados!$A$2:$A$121,0))
A5: 1059 | B5: =INDEX(Dados!$D$2:$D$121,MATCH(1059,Dados!$A$2:$A$121,0)) | C5: =INDEX(Dados!$E$2:$E$121,MATCH(1059,Dados!$A$2:$A$121,0))
A6: 1060 | B6: =INDEX(Dados!$D$2:$D$121,MATCH(1060,Dados!$A$2:$A$121,0)) | C6: =INDEX(Dados!$E$2:$E$121,MATCH(1060,Dados!$A$2:$A$121,0))
A7: 1061 | B7: =INDEX(Dados!$D$2:$D$121,MATCH(1061,Dados!$A$2:$A$121,0)) | C7: =INDEX(Dados!$E$2:$E$121,MATCH(1061,Dados!$A$2:$A$121,0))
A8: 1062 | B8: =INDEX(Dados!$D$2:$D$121,MATCH(1062,Dados!$A$2:$A$121,0)) | C8: =INDEX(Dados!$E$2:$E$121,MATCH(1062,Dados!$A$2:$A$121,0))
A9: 1063 | B9: =INDEX(Dados!$D$2:$D$121,MATCH(1063,Dados!$A$2:$A$121,0)) | C9: =INDEX(Dados!$E$2:$E$121,MATCH(1063,Dados!$A$2:$A$121,0))
A10: 1064 | B10: =INDEX(Dados!$D$2:$D$121,MATCH(1064,Dados!$A$2:$A$121,0)) | C10: =INDEX(Dados!$E$2:$E$121,MATCH(1064,Dados!$A$2:$A$121,0))
A11: 1065 | B11: =INDEX(Dados!$D$2:$D$121,MATCH(1065,Dados!$A$2:$A$121,0)) | C11: =INDEX(Dados!$E$2:$E$121,MATCH(1065,Dados!$A$2:$A$121,0))
A12: 1066 | B12: =INDEX(Dados!$D$2:$D$121,MATCH(1066,Dados!$A$2:$A$121,0)) | C12: =INDEX(Dados!$E$2:$E$121,MATCH(1066,Dados!$A$2:$A$121,0))
A13: 1067 | B13: =INDEX(Dados!$D$2:$D$121,MATCH(1067,Dados!$A$2:$A$121,0)) | C13: =INDEX(Dados!$E$2:$E$121,MATCH(1067,Dados!$A$2:$A$121,0))
A14: 1068 | B14: =INDEX(Dados!$D$2:$D$121,MATCH(1068,Dados!$A$2:$A$121,0)) | C14: =INDEX(Dados!$E$2:$E$121,MATCH(1068,Dados!$A$2:$A$121,0))
A15: 1069 | B15: =INDEX(Dados!$D$2:$D$121,MATCH(1069,Dados!$A$2:$A$121,0)) | C15: =INDEX(Dados!$E$2:$E$121,MATCH(1069,Dados!$A$2:$A$121,0))
A16: 1070 | B16: =INDEX(Dados!$D$2:$D$121,MATCH(1070,Dados!$A$2:$A$121,0)) | C16: =INDEX(Dados!$E$2:$E$121,MATCH(1070,Dados!$A$2:$A$121,0))
A17: 1071 | B17: =INDEX(Dados!$D$2:$D$121,MATCH(1071,Dados!$A$2:$A$121,0)) | C17: =INDEX(Dados!$E$2:$E$121,MATCH(1071,Dados!$A$2:$A$121,0))
A18: 1072 | B18: =INDEX(Dados!$D$2:$D$121,MATCH(1072,Dados!$A$2:$A$121,0)) | C18: =INDEX(Dados!$E$2:$E$121,MATCH(1072,Dados!$A$2:$A$121,0))
A19: 1073 | B19: =INDEX(Dados!$D$2:$D$121,MATCH(1073,Dados!$A$2:$A$121,0)) | C19: =INDEX(Dados!$E$2:$E$121,MATCH(1073,Dados!$A$2:$A$121,0))
A20: 1074 | B20: =INDEX(Dados!$D$2:$D$121,MATCH(1074,Dados!$A$2:$A$121,0)) | C20: =INDEX(Dados!$E$2:$E$121,MATCH(1074,Dados!$A$2:$A$121,0))
A21: 1075 | B21: =INDEX(Dados!$D$2:$D$121,MATCH(1075,Dados!$A$2:$A$121,0)) | C21: =INDEX(Dados!$E$2:$E$121,MATCH(1075,Dados!$A$2:$A$121,0))
A22: 1076 | B22: =INDEX(Dados!$D$2:$D$121,MATCH(1076,Dados!$A$2:$A$121,0)) | C22: =INDEX(Dados!$E$2:$E$121,MATCH(1076,Dados!$A$2:$A$121,0))
A23: 1077 | B23: =INDEX(Dados!$D$2:$D$121,MATCH(1077,Dados!$A$2:$A$121,0)) | C23: =INDEX(Dados!$E$2:$E$121,MATCH(1077,Dados!$A$2:$A$121,0))
A24: 1078 | B24: =INDEX(Dados!$D$2:$D$121,MATCH(1078,Dados!$A$2:$A$121,0)) | C24: =INDEX(Dados!$E$2:$E$121,MATCH(1078,Dados!$A$2:$A$121,0))
A25: 1079 | B25: =INDEX(Dados!$D$2:$D$121,MATCH(1079,Dados!$A$2:$A$121,0)) | C25: =INDEX(Dados!$E$2:$E$121,MATCH(1079,Dados!$A$2:$A$121,0))
A26: 1080 | B26: =INDEX(Dados!$D$2:$D$121,MATCH(1080,Dados!$A$2:$A$121,0)) | C26: =INDEX(Dados!$E$2:$E$121,MATCH(1080,Dados!$A$2:$A$121,0))
A27: 1081 | B27: =INDEX(Dados!$D$2:$D$121,MATCH(1081,Dados!$A$2:$A$121,0)) | C27: =INDEX(Dados!$E$2:$E$121,MATCH(1081,Dados!$A$2:$A$121,0))
A28: 1082 | B28: =INDEX(Dados!$D$2:$D$121,MATCH(1082,Dados!$A$2:$A$121,0)) | C28: =INDEX(Dados!$E$2:$E$121,MATCH(1082,Dados!$A$2:$A$121,0))
A29: 1083 | B29: =INDEX(Dados!$D$2:$D$121,MATCH(1083,Dados!$A$2:$A$121,0)) | C29: =INDEX(Dados!$E$2:$E$121,MATCH(1083,Dados!$A$2:$A$121,0))
A30: 1084 | B30: =INDEX(Dados!$D$2:$D$121,MATCH(1084,Dados!$A$2:$A$121,0)) | C30: =INDEX(Dados!$E$2:$E$121,MATCH(1084,Dados!$A$2:$A$121,0))
A31: 1085 | B31: =INDEX(Dados!$D$2:$D$121,MATCH(1085,Dados!$A$2:$A$121,0)) | C31: =INDEX(Dados!$E$2:$E$121,MATCH(1085,Dados!$A$2:$A$121,0))
A32: 1086 | B32: =INDEX(Dados!$D$2:$D$121,MATCH(1086,Dados!$A$2:$A$121,0)) | C32: =INDEX(Dados!$E$2:$E$121,MATCH(1086,Dados!$A$2:$A$121,0))
A33: 1087 | B33: =INDEX(Dados!$D$2:$D$121,MATCH(1087,Dados!$A$2:$A$121,0)) | C33: =INDEX(Dados!$E$2:$E$121,MATCH(1087,Dados!$A$2:$A$121,0))
A34: 1088 | B34: =INDEX(Dados!$D$2:$D$121,MATCH(1088,Dados!$A$2:$A$121,0)) | C34: =INDEX(Dados!$E$2:$E$121,MATCH(1088,Dados!$A$2:$A$121,0))
A35: 1089 | B35: =INDEX(Dados!$D$2:$D$121,MATCH(1089,Dados!$A$2:$A$121,0)) | C35: =INDEX(Dados!$E$2:$E$121,MATCH(1089,Dados!$A$2:$A$121,0))
A36: 1090 | B36: =INDEX(Dados!$D$2:$D$121,MATCH(1090,Dados!$A$2:$A$121,0)) | C36: =INDEX(Dados!$E$2:$E$121,MATCH(1090,Dados!$A$2:$A$121,0))
A37: 1091 | B37: =INDEX(Dados!$D$2:$D$121,MATCH(1091,Dados!$A$2:$A$121,0)) | C37: =INDEX(Dados!$E$2:$E$121,MATCH(1091,Dados!$A$2:$A$121,0))
A38: 1092 | B38: =INDEX(Dados!$D$2:$D$121,MATCH(1092,Dados!$A$2:$A$121,0)) | C38: =INDEX(Dados!$E$2:$E$121,MATCH(1092,Dados!$A$2:$A$121,0))
A39: 1093 | B39: =INDEX(Dados!$D$2:$D$121,MATCH(1093,Dados!$A$2:$A$121,0)) | C39: =INDEX(Dados!$E$2:$E$121,MATCH(1093,Dados!$A$2:$A$121,0))
A40: 1094 | B40: =INDEX(Dados!$D$2:$D$121,MATCH(1094,Dados!$A$2:$A$121,0)) | C40: =INDEX(Dados!$E$2:$E$121,MATCH(1094,Dados!$A$2:$A$121,0))
...
